2019-08-03 02:18:50,257 [INFO ]  Starting Rasa server on http://localhost:5005
2019-08-03 02:19:04,251 [ERROR]  The model predicted the custom action 'action_get_times', but you didn't configure an endpoint to run this custom action. Please take a look at the docs and set an endpoint configuration via the --endpoints flag. https://rasa.com/docs/rasa/core/actions
2019-08-03 02:19:04,251 [ERROR]  Encountered an exception while running action 'action_get_times'. Bot will continue, but the actions events are lost. Please check the logs of your action server for more information.
2019-08-03 02:19:04,255 [ERROR]  The model predicted the custom action 'action_get_times', but you didn't configure an endpoint to run this custom action. Please take a look at the docs and set an endpoint configuration via the --endpoints flag. https://rasa.com/docs/rasa/core/actions
2019-08-03 02:19:04,255 [ERROR]  Encountered an exception while running action 'action_get_times'. Bot will continue, but the actions events are lost. Please check the logs of your action server for more information.
2019-08-03 02:19:04,262 [ERROR]  The model predicted the custom action 'action_get_times', but you didn't configure an endpoint to run this custom action. Please take a look at the docs and set an endpoint configuration via the --endpoints flag. https://rasa.com/docs/rasa/core/actions
2019-08-03 02:19:04,262 [ERROR]  Encountered an exception while running action 'action_get_times'. Bot will continue, but the actions events are lost. Please check the logs of your action server for more information.
2019-08-03 02:19:04,272 [ERROR]  The model predicted the custom action 'action_get_times', but you didn't configure an endpoint to run this custom action. Please take a look at the docs and set an endpoint configuration via the --endpoints flag. https://rasa.com/docs/rasa/core/actions
2019-08-03 02:19:04,272 [ERROR]  Encountered an exception while running action 'action_get_times'. Bot will continue, but the actions events are lost. Please check the logs of your action server for more information.
2019-08-03 02:19:04,277 [ERROR]  The model predicted the custom action 'action_get_times', but you didn't configure an endpoint to run this custom action. Please take a look at the docs and set an endpoint configuration via the --endpoints flag. https://rasa.com/docs/rasa/core/actions
2019-08-03 02:19:04,277 [ERROR]  Encountered an exception while running action 'action_get_times'. Bot will continue, but the actions events are lost. Please check the logs of your action server for more information.
2019-08-03 02:19:04,279 [ERROR]  The model predicted the custom action 'action_get_times', but you didn't configure an endpoint to run this custom action. Please take a look at the docs and set an endpoint configuration via the --endpoints flag. https://rasa.com/docs/rasa/core/actions
2019-08-03 02:19:04,280 [ERROR]  Encountered an exception while running action 'action_get_times'. Bot will continue, but the actions events are lost. Please check the logs of your action server for more information.
2019-08-03 02:19:04,282 [WARNI]  Circuit breaker tripped. Stopped predicting more actions for sender 'default'
2019-08-03 02:20:21,661 [INFO ]  Starting Rasa server on http://localhost:5005
2019-08-03 02:20:32,190 [ERROR]  Encountered an exception while running action 'action_get_times'. Bot will continue, but the actions events are lost. Please check the logs of your action server for more information.
2019-08-03 02:20:32,233 [ERROR]  Encountered an exception while running action 'action_get_times'. Bot will continue, but the actions events are lost. Please check the logs of your action server for more information.
2019-08-03 02:21:38,545 [ERROR]  Encountered an exception while running action 'action_get_times'. Bot will continue, but the actions events are lost. Please check the logs of your action server for more information.
2019-08-03 02:21:38,561 [ERROR]  Encountered an exception while running action 'action_get_times'. Bot will continue, but the actions events are lost. Please check the logs of your action server for more information.
2019-08-03 02:22:13,572 [INFO ]  Killing Sanic server now.
2019-08-03 02:22:44,350 [INFO ]  Starting Rasa server on http://localhost:5005
2019-08-03 02:24:08,213 [INFO ]  Starting Rasa server on http://localhost:5005
2019-08-03 02:24:18,821 [ERROR]  Encountered an exception while running action 'action_get_times'. Bot will continue, but the actions events are lost. Please check the logs of your action server for more information.
2019-08-03 02:24:44,417 [ERROR]  Encountered an exception while running action 'action_get_times'. Bot will continue, but the actions events are lost. Please check the logs of your action server for more information.
2019-08-03 02:24:45,033 [ERROR]  Encountered an exception while running action 'action_get_times'. Bot will continue, but the actions events are lost. Please check the logs of your action server for more information.
2019-08-03 02:52:52,259 [INFO ]  Starting Rasa server on http://localhost:5005
2019-08-03 02:58:30,533 [INFO ]  Starting Rasa server on http://localhost:5005
2019-08-03 03:07:04,959 [INFO ]  Starting Rasa server on http://localhost:5005
2019-08-03 03:10:50,783 [ERROR]  Exception occurred while handling uri: 'http://localhost:5005/'
Traceback (most recent call last):
  File "/home/razent/anaconda3/lib/python3.7/site-packages/sanic/app.py", line 893, in handle_request
    handler, args, kwargs, uri = self.router.get(request)
  File "/home/razent/anaconda3/lib/python3.7/site-packages/sanic/router.py", line 407, in get
    return self._get(request.path, request.method, "")
  File "/home/razent/anaconda3/lib/python3.7/site-packages/sanic/router.py", line 469, in _get
    raise NotFound("Requested URL {} not found".format(url))
sanic.exceptions.NotFound: Requested URL / not found
2019-08-03 03:10:50,870 [ERROR]  Exception occurred while handling uri: 'http://localhost:5005/favicon.ico'
Traceback (most recent call last):
  File "/home/razent/anaconda3/lib/python3.7/site-packages/sanic/app.py", line 893, in handle_request
    handler, args, kwargs, uri = self.router.get(request)
  File "/home/razent/anaconda3/lib/python3.7/site-packages/sanic/router.py", line 407, in get
    return self._get(request.path, request.method, "")
  File "/home/razent/anaconda3/lib/python3.7/site-packages/sanic/router.py", line 469, in _get
    raise NotFound("Requested URL {} not found".format(url))
sanic.exceptions.NotFound: Requested URL /favicon.ico not found
2019-08-03 03:11:00,368 [ERROR]  Exception occurred while handling uri: 'http://localhost:5005/webhook'
Traceback (most recent call last):
  File "/home/razent/anaconda3/lib/python3.7/site-packages/sanic/app.py", line 893, in handle_request
    handler, args, kwargs, uri = self.router.get(request)
  File "/home/razent/anaconda3/lib/python3.7/site-packages/sanic/router.py", line 407, in get
    return self._get(request.path, request.method, "")
  File "/home/razent/anaconda3/lib/python3.7/site-packages/sanic/router.py", line 469, in _get
    raise NotFound("Requested URL {} not found".format(url))
sanic.exceptions.NotFound: Requested URL /webhook not found
2019-08-03 03:12:38,777 [INFO ]  Starting Rasa server on http://localhost:5005
2019-08-03 03:14:19,514 [ERROR]  Exception occurred while handling uri: 'http://3493a27e.ngrok.io/'
Traceback (most recent call last):
  File "/home/razent/anaconda3/lib/python3.7/site-packages/sanic/app.py", line 893, in handle_request
    handler, args, kwargs, uri = self.router.get(request)
  File "/home/razent/anaconda3/lib/python3.7/site-packages/sanic/router.py", line 407, in get
    return self._get(request.path, request.method, "")
  File "/home/razent/anaconda3/lib/python3.7/site-packages/sanic/router.py", line 469, in _get
    raise NotFound("Requested URL {} not found".format(url))
sanic.exceptions.NotFound: Requested URL / not found
2019-08-03 03:14:20,353 [ERROR]  Exception occurred while handling uri: 'http://3493a27e.ngrok.io/favicon.ico'
Traceback (most recent call last):
  File "/home/razent/anaconda3/lib/python3.7/site-packages/sanic/app.py", line 893, in handle_request
    handler, args, kwargs, uri = self.router.get(request)
  File "/home/razent/anaconda3/lib/python3.7/site-packages/sanic/router.py", line 407, in get
    return self._get(request.path, request.method, "")
  File "/home/razent/anaconda3/lib/python3.7/site-packages/sanic/router.py", line 469, in _get
    raise NotFound("Requested URL {} not found".format(url))
sanic.exceptions.NotFound: Requested URL /favicon.ico not found
2019-08-03 03:31:17,344 [INFO ]  Starting Rasa server on http://localhost:5005
2019-08-03 03:40:51,073 [INFO ]  Starting Rasa server on http://localhost:5005
2019-08-03 03:54:33,177 [INFO ]  Starting Rasa server on http://localhost:5005
2019-08-03 04:04:41,772 [INFO ]  Starting Rasa server on http://localhost:5005
2019-08-03 04:15:26,649 [INFO ]  Starting Rasa server on http://localhost:5005
2019-08-03 04:30:34,717 [INFO ]  Starting Rasa server on http://localhost:5005
2019-08-03 20:17:39,127 [INFO ]  Starting Rasa server on http://localhost:5005
2019-08-03 20:37:09,159 [INFO ]  Starting Rasa server on http://localhost:5005
2019-08-04 11:28:14,506 [INFO ]  Starting Rasa server on http://localhost:5005
2019-08-04 13:18:15,149 [INFO ]  Starting Rasa server on http://localhost:5005
2019-08-04 17:34:34,073 [INFO ]  Starting Rasa server on http://localhost:5005
2019-08-04 21:14:11,037 [INFO ]  Starting Rasa server on http://localhost:5005
2019-08-04 21:15:26,247 [ERROR]  Exception occurred while handling uri: 'http://localhost:5005/version'
Traceback (most recent call last):
  File "/home/razent/anaconda3/lib/python3.7/site-packages/sanic/app.py", line 893, in handle_request
    handler, args, kwargs, uri = self.router.get(request)
  File "/home/razent/anaconda3/lib/python3.7/site-packages/sanic/router.py", line 407, in get
    return self._get(request.path, request.method, "")
  File "/home/razent/anaconda3/lib/python3.7/site-packages/sanic/router.py", line 469, in _get
    raise NotFound("Requested URL {} not found".format(url))
sanic.exceptions.NotFound: Requested URL /version not found
2019-08-04 21:18:47,163 [ERROR]  Exception occurred while handling uri: 'http://localhost:5005/conversations/a0f226ba2e974ae2b92a82b479e900bc/tracker?include_events=ALL'
Traceback (most recent call last):
  File "/home/razent/anaconda3/lib/python3.7/site-packages/sanic/app.py", line 893, in handle_request
    handler, args, kwargs, uri = self.router.get(request)
  File "/home/razent/anaconda3/lib/python3.7/site-packages/sanic/router.py", line 407, in get
    return self._get(request.path, request.method, "")
  File "/home/razent/anaconda3/lib/python3.7/site-packages/sanic/router.py", line 469, in _get
    raise NotFound("Requested URL {} not found".format(url))
sanic.exceptions.NotFound: Requested URL /conversations/a0f226ba2e974ae2b92a82b479e900bc/tracker not found
2019-08-04 21:18:49,640 [ERROR]  Exception occurred while handling uri: 'http://localhost:5005/status'
Traceback (most recent call last):
  File "/home/razent/anaconda3/lib/python3.7/site-packages/sanic/app.py", line 893, in handle_request
    handler, args, kwargs, uri = self.router.get(request)
  File "/home/razent/anaconda3/lib/python3.7/site-packages/sanic/router.py", line 407, in get
    return self._get(request.path, request.method, "")
  File "/home/razent/anaconda3/lib/python3.7/site-packages/sanic/router.py", line 469, in _get
    raise NotFound("Requested URL {} not found".format(url))
sanic.exceptions.NotFound: Requested URL /status not found
2019-08-04 21:19:51,029 [ERROR]  Exception occurred while handling uri: 'http://localhost:5005/version'
Traceback (most recent call last):
  File "/home/razent/anaconda3/lib/python3.7/site-packages/sanic/app.py", line 893, in handle_request
    handler, args, kwargs, uri = self.router.get(request)
  File "/home/razent/anaconda3/lib/python3.7/site-packages/sanic/router.py", line 407, in get
    return self._get(request.path, request.method, "")
  File "/home/razent/anaconda3/lib/python3.7/site-packages/sanic/router.py", line 469, in _get
    raise NotFound("Requested URL {} not found".format(url))
sanic.exceptions.NotFound: Requested URL /version not found
2019-08-04 21:19:51,069 [ERROR]  Exception occurred while handling uri: 'http://localhost:5005/version'
Traceback (most recent call last):
  File "/home/razent/anaconda3/lib/python3.7/site-packages/sanic/app.py", line 893, in handle_request
    handler, args, kwargs, uri = self.router.get(request)
  File "/home/razent/anaconda3/lib/python3.7/site-packages/sanic/router.py", line 407, in get
    return self._get(request.path, request.method, "")
  File "/home/razent/anaconda3/lib/python3.7/site-packages/sanic/router.py", line 469, in _get
    raise NotFound("Requested URL {} not found".format(url))
sanic.exceptions.NotFound: Requested URL /version not found
2019-08-04 21:28:19,306 [ERROR]  Exception occurred while handling uri: 'http://localhost:5005/conversations/a0f226ba2e974ae2b92a82b479e900bc/tracker/events'
Traceback (most recent call last):
  File "/home/razent/anaconda3/lib/python3.7/site-packages/sanic/app.py", line 893, in handle_request
    handler, args, kwargs, uri = self.router.get(request)
  File "/home/razent/anaconda3/lib/python3.7/site-packages/sanic/router.py", line 407, in get
    return self._get(request.path, request.method, "")
  File "/home/razent/anaconda3/lib/python3.7/site-packages/sanic/router.py", line 469, in _get
    raise NotFound("Requested URL {} not found".format(url))
sanic.exceptions.NotFound: Requested URL /conversations/a0f226ba2e974ae2b92a82b479e900bc/tracker/events not found
2019-08-04 21:28:19,309 [WARNI]  Creating event for sender 'a0f226ba2e974ae2b92a82b479e900bc' failed. Error: 404, Not Found, body='b'Error: Requested URL /conversations/a0f226ba2e974ae2b92a82b479e900bc/tracker/events not found''
2019-08-04 21:28:20,392 [ERROR]  Exception occurred while handling uri: 'http://localhost:5005/conversations/a0f226ba2e974ae2b92a82b479e900bc/tracker/events'
Traceback (most recent call last):
  File "/home/razent/anaconda3/lib/python3.7/site-packages/sanic/app.py", line 893, in handle_request
    handler, args, kwargs, uri = self.router.get(request)
  File "/home/razent/anaconda3/lib/python3.7/site-packages/sanic/router.py", line 407, in get
    return self._get(request.path, request.method, "")
  File "/home/razent/anaconda3/lib/python3.7/site-packages/sanic/router.py", line 469, in _get
    raise NotFound("Requested URL {} not found".format(url))
sanic.exceptions.NotFound: Requested URL /conversations/a0f226ba2e974ae2b92a82b479e900bc/tracker/events not found
2019-08-04 21:28:20,394 [WARNI]  Creating event for sender 'a0f226ba2e974ae2b92a82b479e900bc' failed. Error: 404, Not Found, body='b'Error: Requested URL /conversations/a0f226ba2e974ae2b92a82b479e900bc/tracker/events not found''
2019-08-04 21:28:21,787 [ERROR]  Exception occurred while handling uri: 'http://localhost:5005/conversations/a0f226ba2e974ae2b92a82b479e900bc/tracker/events'
Traceback (most recent call last):
  File "/home/razent/anaconda3/lib/python3.7/site-packages/sanic/app.py", line 893, in handle_request
    handler, args, kwargs, uri = self.router.get(request)
  File "/home/razent/anaconda3/lib/python3.7/site-packages/sanic/router.py", line 407, in get
    return self._get(request.path, request.method, "")
  File "/home/razent/anaconda3/lib/python3.7/site-packages/sanic/router.py", line 469, in _get
    raise NotFound("Requested URL {} not found".format(url))
sanic.exceptions.NotFound: Requested URL /conversations/a0f226ba2e974ae2b92a82b479e900bc/tracker/events not found
2019-08-04 21:28:21,789 [WARNI]  Creating event for sender 'a0f226ba2e974ae2b92a82b479e900bc' failed. Error: 404, Not Found, body='b'Error: Requested URL /conversations/a0f226ba2e974ae2b92a82b479e900bc/tracker/events not found''
2019-08-04 21:28:22,290 [ERROR]  Exception occurred while handling uri: 'http://localhost:5005/conversations/a0f226ba2e974ae2b92a82b479e900bc/tracker/events'
Traceback (most recent call last):
  File "/home/razent/anaconda3/lib/python3.7/site-packages/sanic/app.py", line 893, in handle_request
    handler, args, kwargs, uri = self.router.get(request)
  File "/home/razent/anaconda3/lib/python3.7/site-packages/sanic/router.py", line 407, in get
    return self._get(request.path, request.method, "")
  File "/home/razent/anaconda3/lib/python3.7/site-packages/sanic/router.py", line 469, in _get
    raise NotFound("Requested URL {} not found".format(url))
sanic.exceptions.NotFound: Requested URL /conversations/a0f226ba2e974ae2b92a82b479e900bc/tracker/events not found
2019-08-04 21:28:22,291 [WARNI]  Creating event for sender 'a0f226ba2e974ae2b92a82b479e900bc' failed. Error: 404, Not Found, body='b'Error: Requested URL /conversations/a0f226ba2e974ae2b92a82b479e900bc/tracker/events not found''
2019-08-04 21:28:22,384 [ERROR]  Exception occurred while handling uri: 'http://localhost:5005/conversations/a0f226ba2e974ae2b92a82b479e900bc/tracker/events'
Traceback (most recent call last):
  File "/home/razent/anaconda3/lib/python3.7/site-packages/sanic/app.py", line 893, in handle_request
    handler, args, kwargs, uri = self.router.get(request)
  File "/home/razent/anaconda3/lib/python3.7/site-packages/sanic/router.py", line 407, in get
    return self._get(request.path, request.method, "")
  File "/home/razent/anaconda3/lib/python3.7/site-packages/sanic/router.py", line 469, in _get
    raise NotFound("Requested URL {} not found".format(url))
sanic.exceptions.NotFound: Requested URL /conversations/a0f226ba2e974ae2b92a82b479e900bc/tracker/events not found
2019-08-04 21:28:22,385 [WARNI]  Creating event for sender 'a0f226ba2e974ae2b92a82b479e900bc' failed. Error: 404, Not Found, body='b'Error: Requested URL /conversations/a0f226ba2e974ae2b92a82b479e900bc/tracker/events not found''
2019-08-04 21:28:22,811 [ERROR]  Exception occurred while handling uri: 'http://localhost:5005/conversations/a0f226ba2e974ae2b92a82b479e900bc/tracker/events'
Traceback (most recent call last):
  File "/home/razent/anaconda3/lib/python3.7/site-packages/sanic/app.py", line 893, in handle_request
    handler, args, kwargs, uri = self.router.get(request)
  File "/home/razent/anaconda3/lib/python3.7/site-packages/sanic/router.py", line 407, in get
    return self._get(request.path, request.method, "")
  File "/home/razent/anaconda3/lib/python3.7/site-packages/sanic/router.py", line 469, in _get
    raise NotFound("Requested URL {} not found".format(url))
sanic.exceptions.NotFound: Requested URL /conversations/a0f226ba2e974ae2b92a82b479e900bc/tracker/events not found
2019-08-04 21:28:22,813 [WARNI]  Creating event for sender 'a0f226ba2e974ae2b92a82b479e900bc' failed. Error: 404, Not Found, body='b'Error: Requested URL /conversations/a0f226ba2e974ae2b92a82b479e900bc/tracker/events not found''
2019-08-04 21:28:25,343 [ERROR]  Exception occurred while handling uri: 'http://localhost:5005/conversations/a0f226ba2e974ae2b92a82b479e900bc/tracker/events'
Traceback (most recent call last):
  File "/home/razent/anaconda3/lib/python3.7/site-packages/sanic/app.py", line 893, in handle_request
    handler, args, kwargs, uri = self.router.get(request)
  File "/home/razent/anaconda3/lib/python3.7/site-packages/sanic/router.py", line 407, in get
    return self._get(request.path, request.method, "")
  File "/home/razent/anaconda3/lib/python3.7/site-packages/sanic/router.py", line 469, in _get
    raise NotFound("Requested URL {} not found".format(url))
sanic.exceptions.NotFound: Requested URL /conversations/a0f226ba2e974ae2b92a82b479e900bc/tracker/events not found
2019-08-04 21:28:25,345 [WARNI]  Creating event for sender 'a0f226ba2e974ae2b92a82b479e900bc' failed. Error: 404, Not Found, body='b'Error: Requested URL /conversations/a0f226ba2e974ae2b92a82b479e900bc/tracker/events not found''
2019-08-04 21:28:25,693 [ERROR]  Exception occurred while handling uri: 'http://localhost:5005/conversations/a0f226ba2e974ae2b92a82b479e900bc/tracker/events'
Traceback (most recent call last):
  File "/home/razent/anaconda3/lib/python3.7/site-packages/sanic/app.py", line 893, in handle_request
    handler, args, kwargs, uri = self.router.get(request)
  File "/home/razent/anaconda3/lib/python3.7/site-packages/sanic/router.py", line 407, in get
    return self._get(request.path, request.method, "")
  File "/home/razent/anaconda3/lib/python3.7/site-packages/sanic/router.py", line 469, in _get
    raise NotFound("Requested URL {} not found".format(url))
sanic.exceptions.NotFound: Requested URL /conversations/a0f226ba2e974ae2b92a82b479e900bc/tracker/events not found
2019-08-04 21:28:25,694 [WARNI]  Creating event for sender 'a0f226ba2e974ae2b92a82b479e900bc' failed. Error: 404, Not Found, body='b'Error: Requested URL /conversations/a0f226ba2e974ae2b92a82b479e900bc/tracker/events not found''
2019-08-04 21:28:25,773 [ERROR]  Exception occurred while handling uri: 'http://localhost:5005/conversations/a0f226ba2e974ae2b92a82b479e900bc/tracker/events'
Traceback (most recent call last):
  File "/home/razent/anaconda3/lib/python3.7/site-packages/sanic/app.py", line 893, in handle_request
    handler, args, kwargs, uri = self.router.get(request)
  File "/home/razent/anaconda3/lib/python3.7/site-packages/sanic/router.py", line 407, in get
    return self._get(request.path, request.method, "")
  File "/home/razent/anaconda3/lib/python3.7/site-packages/sanic/router.py", line 469, in _get
    raise NotFound("Requested URL {} not found".format(url))
sanic.exceptions.NotFound: Requested URL /conversations/a0f226ba2e974ae2b92a82b479e900bc/tracker/events not found
2019-08-04 21:28:25,774 [WARNI]  Creating event for sender 'a0f226ba2e974ae2b92a82b479e900bc' failed. Error: 404, Not Found, body='b'Error: Requested URL /conversations/a0f226ba2e974ae2b92a82b479e900bc/tracker/events not found''
2019-08-04 21:28:46,359 [ERROR]  Exception occurred while handling uri: 'http://localhost:5005/conversations/a0f226ba2e974ae2b92a82b479e900bc/tracker/events'
Traceback (most recent call last):
  File "/home/razent/anaconda3/lib/python3.7/site-packages/sanic/app.py", line 893, in handle_request
    handler, args, kwargs, uri = self.router.get(request)
  File "/home/razent/anaconda3/lib/python3.7/site-packages/sanic/router.py", line 407, in get
    return self._get(request.path, request.method, "")
  File "/home/razent/anaconda3/lib/python3.7/site-packages/sanic/router.py", line 469, in _get
    raise NotFound("Requested URL {} not found".format(url))
sanic.exceptions.NotFound: Requested URL /conversations/a0f226ba2e974ae2b92a82b479e900bc/tracker/events not found
2019-08-04 21:28:46,362 [WARNI]  Creating event for sender 'a0f226ba2e974ae2b92a82b479e900bc' failed. Error: 404, Not Found, body='b'Error: Requested URL /conversations/a0f226ba2e974ae2b92a82b479e900bc/tracker/events not found''
2019-08-05 22:52:27,883 [INFO ]  Starting Rasa server on http://localhost:5005
2019-08-05 22:52:48,009 [INFO ]  Killing Sanic server now.
2019-08-05 22:53:39,696 [INFO ]  Starting Rasa server on http://localhost:5005
2019-08-05 22:53:49,943 [ERROR]  Encountered an exception while running action 'action_lookUp_en'. Bot will continue, but the actions events are lost. Please check the logs of your action server for more information.
2019-08-05 22:54:42,324 [INFO ]  Killing Sanic server now.
2019-08-05 22:55:11,862 [INFO ]  Starting Rasa server on http://localhost:5005
2019-08-05 22:55:19,854 [ERROR]  Encountered an exception while running action 'action_lookUp_en'. Bot will continue, but the actions events are lost. Please check the logs of your action server for more information.
2019-08-05 22:55:33,620 [INFO ]  Killing Sanic server now.
2019-08-05 23:09:19,064 [INFO ]  Starting Rasa server on http://localhost:5005
2019-08-05 23:09:29,414 [ERROR]  Encountered an exception while running action 'action_lookUp_en'. Bot will continue, but the actions events are lost. Please check the logs of your action server for more information.
2019-08-05 23:10:49,615 [INFO ]  Killing Sanic server now.
2019-08-05 23:18:30,408 [INFO ]  Starting Rasa server on http://localhost:5005
2019-08-05 23:42:25,805 [INFO ]  Starting Rasa server on http://localhost:5005
2019-08-05 23:44:44,063 [INFO ]  Killing Sanic server now.
2019-08-05 23:46:33,529 [INFO ]  Starting Rasa server on http://localhost:5005
2019-08-06 00:46:06,124 [INFO ]  Starting Rasa server on http://localhost:5005
2019-08-06 00:46:18,814 [ERROR]  Failed to run custom action 'action_lookUp_en'. Couldn't connect to the server at 'http://localhost:5055/webhook'. Is the server running? Error: Cannot connect to host localhost:5055 ssl:None [Connection refused]
2019-08-06 00:46:18,814 [ERROR]  Encountered an exception while running action 'action_lookUp_en'. Bot will continue, but the actions events are lost. Please check the logs of your action server for more information.
2019-08-06 00:47:27,648 [INFO ]  Killing Sanic server now.
2019-08-06 00:47:28,069 [ERROR]  Exception occurred while handling uri: 'http://31693fea.ngrok.io/webhooks/facebook/webhook'
Traceback (most recent call last):
  File "/home/razent/anaconda3/lib/python3.7/site-packages/sanic/app.py", line 893, in handle_request
    handler, args, kwargs, uri = self.router.get(request)
  File "/home/razent/anaconda3/lib/python3.7/site-packages/sanic/router.py", line 407, in get
    return self._get(request.path, request.method, "")
  File "/home/razent/anaconda3/lib/python3.7/site-packages/sanic/router.py", line 469, in _get
    raise NotFound("Requested URL {} not found".format(url))
sanic.exceptions.NotFound: Requested URL /webhooks/facebook/webhook not found
2019-08-06 00:47:28,073 [ERROR]  Exception occurred while handling uri: 'http://31693fea.ngrok.io/webhooks/facebook/webhook'
Traceback (most recent call last):
  File "/home/razent/anaconda3/lib/python3.7/site-packages/sanic/app.py", line 893, in handle_request
    handler, args, kwargs, uri = self.router.get(request)
  File "/home/razent/anaconda3/lib/python3.7/site-packages/sanic/router.py", line 407, in get
    return self._get(request.path, request.method, "")
  File "/home/razent/anaconda3/lib/python3.7/site-packages/sanic/router.py", line 469, in _get
    raise NotFound("Requested URL {} not found".format(url))
sanic.exceptions.NotFound: Requested URL /webhooks/facebook/webhook not found
2019-08-06 00:47:42,337 [INFO ]  Starting Rasa server on http://localhost:5005
2021-06-24 10:25:45,179 [ERROR]  Exception occurred while handling uri: 'http://localhost:5005/favicon.ico'
Traceback (most recent call last):
  File "/home/quangcuong/anaconda3/envs/rasa/lib/python3.6/site-packages/sanic/app.py", line 893, in handle_request
    handler, args, kwargs, uri = self.router.get(request)
  File "/home/quangcuong/anaconda3/envs/rasa/lib/python3.6/site-packages/sanic/router.py", line 407, in get
    return self._get(request.path, request.method, "")
  File "/home/quangcuong/anaconda3/envs/rasa/lib/python3.6/site-packages/sanic/router.py", line 469, in _get
    raise NotFound("Requested URL {} not found".format(url))
sanic.exceptions.NotFound: Requested URL /favicon.ico not found
2021-06-24 14:50:14,463 [ERROR]  Unable to start server
Traceback (most recent call last):
  File "/home/quangcuong/anaconda3/envs/rasa/lib/python3.6/site-packages/sanic/server.py", line 745, in serve
    http_server = loop.run_until_complete(server_coroutine)
  File "uvloop/loop.pyx", line 1456, in uvloop.loop.Loop.run_until_complete
  File "uvloop/loop.pyx", line 1727, in create_server
OSError: [Errno 98] error while attempting to bind on address ('0.0.0.0', 5005): address already in use
2021-06-24 14:53:08,020 [ERROR]  Unable to start server
Traceback (most recent call last):
  File "/home/quangcuong/anaconda3/envs/rasa/lib/python3.6/site-packages/sanic/server.py", line 745, in serve
    http_server = loop.run_until_complete(server_coroutine)
  File "uvloop/loop.pyx", line 1456, in uvloop.loop.Loop.run_until_complete
  File "uvloop/loop.pyx", line 1727, in create_server
OSError: [Errno 98] error while attempting to bind on address ('0.0.0.0', 5005): address already in use
2021-06-24 14:55:19,901 [ERROR]  Unable to start server
Traceback (most recent call last):
  File "/home/quangcuong/anaconda3/envs/rasa/lib/python3.6/site-packages/sanic/server.py", line 745, in serve
    http_server = loop.run_until_complete(server_coroutine)
  File "uvloop/loop.pyx", line 1456, in uvloop.loop.Loop.run_until_complete
  File "uvloop/loop.pyx", line 1727, in create_server
OSError: [Errno 98] error while attempting to bind on address ('0.0.0.0', 5005): address already in use
2021-06-24 14:57:02,748 [ERROR]  Unable to start server
Traceback (most recent call last):
  File "/home/quangcuong/anaconda3/envs/rasa/lib/python3.6/site-packages/sanic/server.py", line 745, in serve
    http_server = loop.run_until_complete(server_coroutine)
  File "uvloop/loop.pyx", line 1456, in uvloop.loop.Loop.run_until_complete
  File "uvloop/loop.pyx", line 1727, in create_server
OSError: [Errno 98] error while attempting to bind on address ('0.0.0.0', 5005): address already in use
2021-06-24 16:06:18,601 [ERROR]  Unable to start server
Traceback (most recent call last):
  File "/home/quangcuong/anaconda3/envs/rasa/lib/python3.6/site-packages/sanic/server.py", line 745, in serve
    http_server = loop.run_until_complete(server_coroutine)
  File "uvloop/loop.pyx", line 1456, in uvloop.loop.Loop.run_until_complete
  File "uvloop/loop.pyx", line 1727, in create_server
OSError: [Errno 98] error while attempting to bind on address ('0.0.0.0', 5005): address already in use
2021-06-25 16:40:10,952 [ERROR]  Unable to start server
Traceback (most recent call last):
  File "/home/quangcuong/anaconda3/envs/rasa/lib/python3.6/site-packages/sanic/server.py", line 745, in serve
    http_server = loop.run_until_complete(server_coroutine)
  File "uvloop/loop.pyx", line 1456, in uvloop.loop.Loop.run_until_complete
  File "uvloop/loop.pyx", line 1727, in create_server
OSError: [Errno 98] error while attempting to bind on address ('0.0.0.0', 5005): address already in use
2021-06-25 16:44:23,026 [ERROR]  Unable to start server
Traceback (most recent call last):
  File "/home/quangcuong/anaconda3/envs/rasa/lib/python3.6/site-packages/sanic/server.py", line 745, in serve
    http_server = loop.run_until_complete(server_coroutine)
  File "uvloop/loop.pyx", line 1456, in uvloop.loop.Loop.run_until_complete
  File "uvloop/loop.pyx", line 1727, in create_server
OSError: [Errno 98] error while attempting to bind on address ('0.0.0.0', 5005): address already in use
2021-06-25 16:47:34,208 [ERROR]  Experienced exception while trying to serve
Traceback (most recent call last):
  File "/home/quangcuong/anaconda3/envs/rasa/lib/python3.6/site-packages/tensorflow/python/framework/ops.py", line 2409, in get_attr
    c_api.TF_OperationGetAttrValueProto(self._c_op, name, buf)
tensorflow.python.framework.errors_impl.InvalidArgumentError: Operation 'lstm/while/MatMul_1' has no attr named '_XlaCompile'.

During handling of the above exception, another exception occurred:

Traceback (most recent call last):
  File "/home/quangcuong/anaconda3/envs/rasa/lib/python3.6/site-packages/tensorflow/python/ops/gradients_impl.py", line 415, in _MaybeCompile
    xla_compile = op.get_attr("_XlaCompile")
  File "/home/quangcuong/anaconda3/envs/rasa/lib/python3.6/site-packages/tensorflow/python/framework/ops.py", line 2413, in get_attr
    raise ValueError(str(e))
ValueError: Operation 'lstm/while/MatMul_1' has no attr named '_XlaCompile'.

During handling of the above exception, another exception occurred:

Traceback (most recent call last):
  File "/home/quangcuong/anaconda3/envs/rasa/lib/python3.6/site-packages/sanic/app.py", line 1096, in run
    serve(**server_settings)
  File "/home/quangcuong/anaconda3/envs/rasa/lib/python3.6/site-packages/sanic/server.py", line 742, in serve
    trigger_events(before_start, loop)
  File "/home/quangcuong/anaconda3/envs/rasa/lib/python3.6/site-packages/sanic/server.py", line 604, in trigger_events
    loop.run_until_complete(result)
  File "uvloop/loop.pyx", line 1450, in uvloop.loop.Loop.run_until_complete
  File "uvloop/loop.pyx", line 1443, in uvloop.loop.Loop.run_until_complete
  File "uvloop/loop.pyx", line 1351, in uvloop.loop.Loop.run_forever
  File "uvloop/loop.pyx", line 519, in uvloop.loop.Loop._run
  File "uvloop/loop.pyx", line 436, in uvloop.loop.Loop._on_idle
  File "uvloop/cbhandles.pyx", line 90, in uvloop.loop.Handle._run
  File "uvloop/cbhandles.pyx", line 68, in uvloop.loop.Handle._run
  File "/home/quangcuong/anaconda3/envs/rasa/lib/python3.6/site-packages/rasa/core/run.py", line 203, in load_agent_on_start
    action_endpoint=endpoints.action,
  File "/home/quangcuong/anaconda3/envs/rasa/lib/python3.6/site-packages/rasa/core/agent.py", line 232, in load_agent
    remote_storage=remote_storage,
  File "/home/quangcuong/anaconda3/envs/rasa/lib/python3.6/site-packages/rasa/core/agent.py", line 877, in load_local_model
    remote_storage=remote_storage,
  File "/home/quangcuong/anaconda3/envs/rasa/lib/python3.6/site-packages/rasa/core/agent.py", line 370, in load
    ensemble = PolicyEnsemble.load(core_model) if core_model else None
  File "/home/quangcuong/anaconda3/envs/rasa/lib/python3.6/site-packages/rasa/core/policies/ensemble.py", line 232, in load
    policy = policy_cls.load(policy_path)
  File "/home/quangcuong/anaconda3/envs/rasa/lib/python3.6/site-packages/rasa/core/policies/keras_policy.py", line 320, in load
    model = load_model(model_file)
  File "/home/quangcuong/anaconda3/envs/rasa/lib/python3.6/site-packages/tensorflow/python/keras/engine/saving.py", line 275, in load_model
    model._make_train_function()
  File "/home/quangcuong/anaconda3/envs/rasa/lib/python3.6/site-packages/tensorflow/python/keras/engine/training.py", line 1919, in _make_train_function
    [self.total_loss] + metrics_tensors)
  File "/home/quangcuong/anaconda3/envs/rasa/lib/python3.6/site-packages/tensorflow/python/keras/engine/training.py", line 1895, in _make_train_function_helper
    params=self._collected_trainable_weights, loss=self.total_loss)
  File "/home/quangcuong/anaconda3/envs/rasa/lib/python3.6/site-packages/tensorflow/python/keras/optimizers.py", line 259, in get_updates
    grads = self.get_gradients(loss, params)
  File "/home/quangcuong/anaconda3/envs/rasa/lib/python3.6/site-packages/tensorflow/python/keras/optimizers.py", line 93, in get_gradients
    grads = K.gradients(loss, params)
  File "/home/quangcuong/anaconda3/envs/rasa/lib/python3.6/site-packages/tensorflow/python/keras/backend.py", line 3216, in gradients
    loss, variables, colocate_gradients_with_ops=True)
  File "/home/quangcuong/anaconda3/envs/rasa/lib/python3.6/site-packages/tensorflow/python/ops/gradients_impl.py", line 664, in gradients
    unconnected_gradients)
  File "/home/quangcuong/anaconda3/envs/rasa/lib/python3.6/site-packages/tensorflow/python/ops/gradients_impl.py", line 965, in _GradientsHelper
    lambda: grad_fn(op, *out_grads))
  File "/home/quangcuong/anaconda3/envs/rasa/lib/python3.6/site-packages/tensorflow/python/ops/gradients_impl.py", line 420, in _MaybeCompile
    return grad_fn()  # Exit early
  File "/home/quangcuong/anaconda3/envs/rasa/lib/python3.6/site-packages/tensorflow/python/ops/gradients_impl.py", line 965, in <lambda>
    lambda: grad_fn(op, *out_grads))
  File "/home/quangcuong/anaconda3/envs/rasa/lib/python3.6/site-packages/tensorflow/python/ops/math_grad.py", line 1132, in _MatMulGrad
    grad_b = gen_math_ops.mat_mul(a, grad, transpose_a=True)
  File "/home/quangcuong/anaconda3/envs/rasa/lib/python3.6/site-packages/tensorflow/python/ops/gen_math_ops.py", line 5333, in mat_mul
    name=name)
  File "/home/quangcuong/anaconda3/envs/rasa/lib/python3.6/site-packages/tensorflow/python/framework/op_def_library.py", line 788, in _apply_op_helper
    op_def=op_def)
  File "/home/quangcuong/anaconda3/envs/rasa/lib/python3.6/site-packages/tensorflow/python/util/deprecation.py", line 507, in new_func
    return func(*args, **kwargs)
  File "/home/quangcuong/anaconda3/envs/rasa/lib/python3.6/site-packages/tensorflow/python/framework/ops.py", line 3300, in create_op
    op_def=op_def)
  File "/home/quangcuong/anaconda3/envs/rasa/lib/python3.6/site-packages/tensorflow/python/framework/ops.py", line 1838, in __init__
    self._control_flow_post_processing()
  File "/home/quangcuong/anaconda3/envs/rasa/lib/python3.6/site-packages/tensorflow/python/framework/ops.py", line 1849, in _control_flow_post_processing
    self._control_flow_context.AddOp(self)
  File "/home/quangcuong/anaconda3/envs/rasa/lib/python3.6/site-packages/tensorflow/python/ops/control_flow_ops.py", line 2561, in AddOp
    self._AddOpInternal(op)
  File "/home/quangcuong/anaconda3/envs/rasa/lib/python3.6/site-packages/tensorflow/python/ops/control_flow_ops.py", line 2582, in _AddOpInternal
    real_x = self.AddValue(x)
  File "/home/quangcuong/anaconda3/envs/rasa/lib/python3.6/site-packages/tensorflow/python/ops/control_flow_ops.py", line 2514, in AddValue
    real_val = grad_ctxt.grad_state.GetRealValue(val)
  File "/home/quangcuong/anaconda3/envs/rasa/lib/python3.6/site-packages/tensorflow/python/ops/control_flow_ops.py", line 1146, in GetRealValue
    history_value = cur_grad_state.AddForwardAccumulator(cur_value)
  File "/home/quangcuong/anaconda3/envs/rasa/lib/python3.6/site-packages/tensorflow/python/ops/control_flow_ops.py", line 1018, in AddForwardAccumulator
    enter_acc = self.forward_context.AddValue(acc)
  File "/home/quangcuong/anaconda3/envs/rasa/lib/python3.6/site-packages/tensorflow/python/ops/control_flow_ops.py", line 2526, in AddValue
    parallel_iterations=self._parallel_iterations)
  File "/home/quangcuong/anaconda3/envs/rasa/lib/python3.6/site-packages/tensorflow/python/ops/control_flow_ops.py", line 259, in _Enter
    data, frame_name, is_constant, parallel_iterations, name=name)
  File "/home/quangcuong/anaconda3/envs/rasa/lib/python3.6/site-packages/tensorflow/python/ops/gen_control_flow_ops.py", line 207, in enter
    parallel_iterations=parallel_iterations, name=name)
  File "/home/quangcuong/anaconda3/envs/rasa/lib/python3.6/site-packages/tensorflow/python/framework/op_def_library.py", line 788, in _apply_op_helper
    op_def=op_def)
  File "/home/quangcuong/anaconda3/envs/rasa/lib/python3.6/site-packages/tensorflow/python/util/deprecation.py", line 507, in new_func
    return func(*args, **kwargs)
  File "/home/quangcuong/anaconda3/envs/rasa/lib/python3.6/site-packages/tensorflow/python/framework/ops.py", line 3300, in create_op
    op_def=op_def)
  File "/home/quangcuong/anaconda3/envs/rasa/lib/python3.6/site-packages/tensorflow/python/framework/ops.py", line 1832, in __init__
    for i, output_type in enumerate(output_types)
  File "/home/quangcuong/anaconda3/envs/rasa/lib/python3.6/site-packages/tensorflow/python/framework/ops.py", line 1832, in <listcomp>
    for i, output_type in enumerate(output_types)
  File "/home/quangcuong/anaconda3/envs/rasa/lib/python3.6/site-packages/tensorflow/python/framework/ops.py", line 303, in __init__
    def __init__(self, op, value_index, dtype):
KeyboardInterrupt
